<?xml version="1.0"?>
<!-- This URDF was automatically created by SolidWorks to URDF Exporter! Originally created by Stephen Brawner (brawner@gmail.com) 
     Commit Version: 1.6.0-4-g7f85cfe  Build Version: 1.6.7995.38578
     For more information, please see http://wiki.ros.org/sw_urdf_exporter -->
<robot
  name="mobile_robot" xmlns:xacro="http://ros.org/wiki/xacro">

 # defining color
  <xacro:macro name="base_link_color">
      <visual>
      <material>
          <ambient>0.40 0.40 0.40 1.0</ambient>
          <diffuse>0.40 0.40 0.40 1.0</diffuse>
          <specular>0.1 0.1 0.1 1</specular>
          <emissive>0 0 0 0</emissive>
      </material>
      </visual>
  </xacro:macro>

<xacro:macro name="wheel_color">
      <visual>
      <material>
          <ambient>0.25 0.25 0.25 1.0</ambient>
          <diffuse>0.25 0.25 0.25 1.0</diffuse>
          <specular>0.1 0.1 0.1 1</specular>
          <emissive>0 0 0 0</emissive>
      </material>
      </visual>
  </xacro:macro>


  # Add this before base link
  <link name="dummy_link"></link>

 

  <link
    name="base_link">
    <inertial>
      <origin
        xyz="-0.0005957 2.423E-08 0.030374"
        rpy="0 0 0" />
      <mass
        value="102.84" />
      <inertia
        ixx="2.2901"
        ixy="-3.0555E-07"
        ixz="0.0027335"
        iyy="7.6029"
        iyz="2.2414E-07"
        izz="8.7762" />
    </inertial>
    <visual>
      <origin
        xyz="0 0 0"
        rpy="0 0 0" />
      <geometry>
        <mesh
          filename="package://mobile_robot/meshes/base_link.STL" />
      </geometry>
      <material
        name="">
        <color
          rgba="0.79216 0.81961 0.93333 1" />
      </material>
    </visual>
    <collision>
      <origin
        xyz="0 0 0"
        rpy="0 0 0" />
      <geometry>
        <mesh
          filename="package://mobile_robot/meshes/base_link.STL" />
      </geometry>
    </collision>
  </link>

 # Add this after base link
  <joint name="dummy_joint" type="fixed">
      <origin rpy="-1.5708 0 0" xyz="0 0 0" />
      <parent link="dummy_link"/>
      <child link="base_link"/>
  </joint>

  <link
    name="link_1a">
    <inertial>
      <origin
        xyz="-0.039563 0.0175 -0.051981"
        rpy="0 0 0" />
      <mass
        value="0.50283" />
      <inertia
        ixx="0.0013292"
        ixy="3.8948E-20"
        ixz="-0.00067322"
        iyy="0.0022628"
        iyz="4.5606E-20"
        izz="0.0010363" />
    </inertial>
    <visual>
      <origin
        xyz="0 0 0"
        rpy="0 0 0" />
      <geometry>
        <mesh
          filename="package://mobile_robot/meshes/link_1a.STL" />
      </geometry>
      <material
        name="">
        <color
          rgba="0.79216 0.81961 0.93333 1" />
      </material>
    </visual>
    <collision>
      <origin
        xyz="0 0 0"
        rpy="0 0 0" />
      <geometry>
        <mesh
          filename="package://mobile_robot/meshes/link_1a.STL" />
      </geometry>
    </collision>
  </link>
  <joint
    name="joint_1a"
    type="fixed">
    <origin
      xyz="-0.2365 0.06 0.219"
      rpy="1.5707963267949 0 -1.83259571459404" />
    <parent
      link="base_link" />
    <child
      link="link_1a" />
    <axis
      xyz="0 0 0" />
  </joint>
  <link
    name="link_2a">
    <inertial>
      <origin
        xyz="0.053752 5.5511E-17 0.012418"
        rpy="0 0 0" />
      <mass
        value="0.83985" />
      <inertia
        ixx="0.0010103"
        ixy="3.5159E-18"
        ixz="0.00045632"
        iyy="0.0038041"
        iyz="1.2247E-19"
        izz="0.0039259" />
    </inertial>
    <visual>
      <origin
        xyz="0 0 0"
        rpy="0 0 0" />
      <geometry>
        <mesh
          filename="package://mobile_robot/meshes/link_2a.STL" />
      </geometry>
      <material
        name="">
        <color
          rgba="0.79216 0.81961 0.93333 1" />
      </material>
    </visual>
    <collision>
      <origin
        xyz="0 0 0"
        rpy="0 0 0" />
      <geometry>
        <mesh
          filename="package://mobile_robot/meshes/link_2a.STL" />
      </geometry>
    </collision>
  </link>
  <joint
    name="joint_2a"
    type="fixed">
    <origin
      xyz="-0.065529 0.0175 -0.09221"
      rpy="3.1416 -1.0472 3.1416" />
    <parent
      link="link_1a" />
    <child
      link="link_2a" />
    <axis
      xyz="0 0 0" />
  </joint>
  <link
    name="link_3a">
    <inertial>
      <origin
        xyz="0.042962 0 -0.10116"
        rpy="0 0 0" />
      <mass
        value="0.35188" />
      <inertia
        ixx="0.0012021"
        ixy="2.7184E-20"
        ixz="0.00020915"
        iyy="0.0014526"
        iyz="-1.5189E-20"
        izz="0.00031657" />
    </inertial>
    <visual>
      <origin
        xyz="0 0 0"
        rpy="0 0 0" />
      <geometry>
        <mesh
          filename="package://mobile_robot/meshes/link_3a.STL" />
      </geometry>
      <material
        name="">
        <color
          rgba="0.79216 0.81961 0.93333 1" />
      </material>
    </visual>
    <collision>
      <origin
        xyz="0 0 0"
        rpy="0 0 0" />
      <geometry>
        <mesh
          filename="package://mobile_robot/meshes/link_3a.STL" />
      </geometry>
    </collision>
  </link>
  <joint
    name="joint_3a"
    type="revolute">
    <origin
      xyz="0.14328 0 -0.028284"
      rpy="2.3562 0 -1.5708" />
    <parent
      link="link_2a" />
    <child
      link="link_3a" />
    <axis
      xyz="0 0 1" />
    <limit
      lower="-3.14"
      upper="3.14"
      effort="100"
      velocity="0" />
  </joint>
  <link
    name="wheel_a">
    <inertial>
      <origin
        xyz="2.7756E-17 -0.00032568 -1.1102E-16"
        rpy="0 0 0" />
      <mass
        value="1.5436" />
      <inertia
        ixx="0.0055361"
        ixy="1.2164E-18"
        ixz="-4.5536E-18"
        iyy="0.0095744"
        iyz="8.0969E-19"
        izz="0.0055361" />
    </inertial>
    <visual>
      <origin
        xyz="0 0 0"
        rpy="0 0 0" />
      <geometry>
        <mesh
          filename="package://mobile_robot/meshes/wheel_a.STL" />
      </geometry>
      <material
        name="">
        <color
          rgba="0.79216 0.81961 0.93333 1" />
      </material>
    </visual>
    <collision>
      <origin
        xyz="0 0 0"
        rpy="0 0 0" />
      <geometry>
        <mesh
          filename="package://mobile_robot/meshes/wheel_a.STL" />
      </geometry>
    </collision>
  </link>
  <joint
    name="wheel_joint_a"
    type="continuous">
    <origin
      xyz="0 0 -0.181"
      rpy="3.1416 -1.007 -1.5708" />
    <parent
      link="link_3a" />
    <child
      link="wheel_a" />
    <axis
      xyz="0 1 0" />
  </joint>
  <link
    name="link_1b">
    <inertial>
      <origin
        xyz="-0.039563006306928 0.0175 -0.0519808529026815"
        rpy="0 0 0" />
      <mass
        value="0.502830874607731" />
      <inertia
        ixx="0.00132920865544275"
        ixy="-1.25790800504412E-19"
        ixz="-0.000673218555283649"
        iyy="0.0022628023452921"
        iyz="-1.36434319248097E-19"
        izz="0.00103625499341509" />
    </inertial>
    <visual>
      <origin
        xyz="0 0 0"
        rpy="0 0 0" />
      <geometry>
        <mesh
          filename="package://mobile_robot/meshes/link_1b.STL" />
      </geometry>
      <material
        name="">
        <color
          rgba="0.792156862745098 0.819607843137255 0.933333333333333 1" />
      </material>
    </visual>
    <collision>
      <origin
        xyz="0 0 0"
        rpy="0 0 0" />
      <geometry>
        <mesh
          filename="package://mobile_robot/meshes/link_1b.STL" />
      </geometry>
    </collision>
  </link>
  <joint
    name="joint_1b"
    type="fixed">
    <origin
      xyz="-0.2365 0.06 -0.254"
      rpy="1.5708 0 -1.8326" />
    <parent
      link="base_link" />
    <child
      link="link_1b" />
    <axis
      xyz="0 0 0" />
  </joint>
  <link
    name="link_2b">
    <inertial>
      <origin
        xyz="0.053752102153806 2.77555756156289E-17 0.012417867361845"
        rpy="0 0 0" />
      <mass
        value="0.839852789561809" />
      <inertia
        ixx="0.00101033633411804"
        ixy="2.18377621542409E-18"
        ixz="0.000456321325264451"
        iyy="0.00380409172847023"
        iyz="-4.12559137247788E-19"
        izz="0.00392594422883486" />
    </inertial>
    <visual>
      <origin
        xyz="0 0 0"
        rpy="0 0 0" />
      <geometry>
        <mesh
          filename="package://mobile_robot/meshes/link_2b.STL" />
      </geometry>
      <material
        name="">
        <color
          rgba="0.792156862745098 0.819607843137255 0.933333333333333 1" />
      </material>
    </visual>
    <collision>
      <origin
        xyz="0 0 0"
        rpy="0 0 0" />
      <geometry>
        <mesh
          filename="package://mobile_robot/meshes/link_2b.STL" />
      </geometry>
    </collision>
  </link>
  <joint
    name="joint_2b"
    type="fixed">
    <origin
      xyz="-0.065529 0.0175 -0.09221"
      rpy="3.1416 -1.0472 3.1416" />
    <parent
      link="link_1b" />
    <child
      link="link_2b" />
    <axis
      xyz="0 0 0" />
  </joint>
  <link
    name="link_3b">
    <inertial>
      <origin
        xyz="0.0429616361908162 0 -0.101156749416517"
        rpy="0 0 0" />
      <mass
        value="0.351878584084715" />
      <inertia
        ixx="0.00120209563686855"
        ixy="9.90467630203431E-20"
        ixz="0.000209154549476735"
        iyy="0.00145264496019541"
        iyz="-2.64435583025856E-20"
        izz="0.000316574406941379" />
    </inertial>
    <visual>
      <origin
        xyz="0 0 0"
        rpy="0 0 0" />
      <geometry>
        <mesh
          filename="package://mobile_robot/meshes/link_3b.STL" />
      </geometry>
      <material
        name="">
        <color
          rgba="0.792156862745098 0.819607843137255 0.933333333333333 1" />
      </material>
    </visual>
    <collision>
      <origin
        xyz="0 0 0"
        rpy="0 0 0" />
      <geometry>
        <mesh
          filename="package://mobile_robot/meshes/link_3b.STL" />
      </geometry>
    </collision>
  </link>
  <joint
    name="joint_3b"
    type="revolute">
    <origin
      xyz="0.14328 0 -0.028284"
      rpy="-2.3562 0 1.5708" />
    <parent
      link="link_2b" />
    <child
      link="link_3b" />
    <axis
      xyz="0 0 1" />
    <limit
      lower="-3.14"
      upper="3.14"
      effort="100"
      velocity="0" />
  </joint>
  <link
    name="wheel_b">
    <inertial>
      <origin
        xyz="0 -0.000325682611319128 0"
        rpy="0 0 0" />
      <mass
        value="1.54358472058328" />
      <inertia
        ixx="0.00553612528961153"
        ixy="2.24148890264748E-19"
        ixz="-2.16840434497101E-19"
        iyy="0.00957443122522794"
        iyz="3.35832558184495E-19"
        izz="0.00553612528961153" />
    </inertial>
    <visual>
      <origin
        xyz="0 0 0"
        rpy="0 0 0" />
      <geometry>
        <mesh
          filename="package://mobile_robot/meshes/wheel_b.STL" />
      </geometry>
      <material
        name="">
        <color
          rgba="0.792156862745098 0.819607843137255 0.933333333333333 1" />
      </material>
    </visual>
    <collision>
      <origin
        xyz="0 0 0"
        rpy="0 0 0" />
      <geometry>
        <mesh
          filename="package://mobile_robot/meshes/wheel_b.STL" />
      </geometry>
    </collision>
  </link>
  <joint
    name="wheel_joint_b"
    type="continuous">
    <origin
      xyz="0 0 -0.181"
      rpy="0 0.5132 1.5708" />
    <parent
      link="link_3b" />
    <child
      link="wheel_b" />
    <axis
      xyz="0 1 0" />
  </joint>
  <link
    name="link_1c">
    <inertial>
      <origin
        xyz="-0.0395630063069281 0.0175 -0.0519808529026815"
        rpy="0 0 0" />
      <mass
        value="0.502830874607731" />
      <inertia
        ixx="0.00132920865544275"
        ixy="-6.1654949534134E-20"
        ixz="-0.00067321855528365"
        iyy="0.0022628023452921"
        iyz="7.59540540768857E-21"
        izz="0.00103625499341509" />
    </inertial>
    <visual>
      <origin
        xyz="0 0 0"
        rpy="0 0 0" />
      <geometry>
        <mesh
          filename="package://mobile_robot/meshes/link_1c.STL" />
      </geometry>
      <material
        name="">
        <color
          rgba="0.792156862745098 0.819607843137255 0.933333333333333 1" />
      </material>
    </visual>
    <collision>
      <origin
        xyz="0 0 0"
        rpy="0 0 0" />
      <geometry>
        <mesh
          filename="package://mobile_robot/meshes/link_1c.STL" />
      </geometry>
    </collision>
  </link>
  <joint
    name="joint_1c"
    type="fixed">
    <origin
      xyz="0.2365 0.06 -0.254"
      rpy="1.5708 0 0.39187" />
    <parent
      link="base_link" />
    <child
      link="link_1c" />
    <axis
      xyz="0 0 0" />
  </joint>
  <link
    name="link_2c">
    <inertial>
      <origin
        xyz="0.0537521021538061 5.55111512312578E-17 0.012417867361845"
        rpy="0 0 0" />
      <mass
        value="0.83985278956181" />
      <inertia
        ixx="0.00101033633411805"
        ixy="2.32765525104793E-18"
        ixz="0.000456321325264452"
        iyy="0.00380409172847023"
        iyz="3.76989989844925E-20"
        izz="0.00392594422883488" />
    </inertial>
    <visual>
      <origin
        xyz="0 0 0"
        rpy="0 0 0" />
      <geometry>
        <mesh
          filename="package://mobile_robot/meshes/link_2c.STL" />
      </geometry>
      <material
        name="">
        <color
          rgba="0.792156862745098 0.819607843137255 0.933333333333333 1" />
      </material>
    </visual>
    <collision>
      <origin
        xyz="0 0 0"
        rpy="0 0 0" />
      <geometry>
        <mesh
          filename="package://mobile_robot/meshes/link_2c.STL" />
      </geometry>
    </collision>
  </link>
  <joint
    name="joint_2c"
    type="fixed">
    <origin
      xyz="-0.074188 0.0175 -0.08461"
      rpy="3.1416 0.39353 0" />
    <parent
      link="link_1c" />
    <child
      link="link_2c" />
    <axis
      xyz="0 0 0" />
  </joint>
  <link
    name="link_3c">
    <inertial>
      <origin
        xyz="0.0429616361908162 0.0175 0.0248432505834826"
        rpy="0 0 0" />
      <mass
        value="0.351878584084715" />
      <inertia
        ixx="0.00120209563686855"
        ixy="-1.83460442767597E-20"
        ixz="0.000209154549476735"
        iyy="0.00145264496019541"
        iyz="1.21046182851412E-19"
        izz="0.000316574406941379" />
    </inertial>
    <visual>
      <origin
        xyz="0 0 0"
        rpy="0 0 0" />
      <geometry>
        <mesh
          filename="package://mobile_robot/meshes/link_3c.STL" />
      </geometry>
      <material
        name="">
        <color
          rgba="0.792156862745098 0.819607843137255 0.933333333333333 1" />
      </material>
    </visual>
    <collision>
      <origin
        xyz="0 0 0"
        rpy="0 0 0" />
      <geometry>
        <mesh
          filename="package://mobile_robot/meshes/link_3c.STL" />
      </geometry>
    </collision>
  </link>
  <joint
    name="joint_3c"
    type="fixed">
    <origin
      xyz="0.24475 0 0.048437"
      rpy="2.3562 0 -1.5708" />
    <parent
      link="link_2c" />
    <child
      link="link_3c" />
    <axis
      xyz="0 0 0" />
  </joint>
  <link
    name="wheel_c">
    <inertial>
      <origin
        xyz="5.55111512312578E-17 -0.00032568261131935 -1.11022302462516E-16"
        rpy="0 0 0" />
      <mass
        value="1.54358472058328" />
      <inertia
        ixx="0.00553612528961155"
        ixy="4.16479688089891E-19"
        ixz="-1.30104260698261E-18"
        iyy="0.00957443122522799"
        iyz="5.28611900711342E-19"
        izz="0.00553612528961156" />
    </inertial>
    <visual>
      <origin
        xyz="0 0 0"
        rpy="0 0 0" />
      <geometry>
        <mesh
          filename="package://mobile_robot/meshes/wheel_c.STL" />
      </geometry>
      <material
        name="">
        <color
          rgba="0.792156862745098 0.819607843137255 0.933333333333333 1" />
      </material>
    </visual>
    <collision>
      <origin
        xyz="0 0 0"
        rpy="0 0 0" />
      <geometry>
        <mesh
          filename="package://mobile_robot/meshes/wheel_c.STL" />
      </geometry>
    </collision>
  </link>
  <joint
    name="wheel_joint_c"
    type="continuous">
    <origin
      xyz="0 0.0175 -0.055"
      rpy="0 0.48844 1.5708" />
    <parent
      link="link_3c" />
    <child
      link="wheel_c" />
    <axis
      xyz="0 1 0" />
  </joint>
  <link
    name="link_1d">
    <inertial>
      <origin
        xyz="-0.0395630063069281 0.0175 -0.0519808529026815"
        rpy="0 0 0" />
      <mass
        value="0.502830874607731" />
      <inertia
        ixx="0.00132920865544275"
        ixy="-1.2946873241384E-20"
        ixz="-0.000673218555283649"
        iyy="0.0022628023452921"
        iyz="1.94753182428243E-22"
        izz="0.00103625499341509" />
    </inertial>
    <visual>
      <origin
        xyz="0 0 0"
        rpy="0 0 0" />
      <geometry>
        <mesh
          filename="package://mobile_robot/meshes/link_1d.STL" />
      </geometry>
      <material
        name="">
        <color
          rgba="0.792156862745098 0.819607843137255 0.933333333333333 1" />
      </material>
    </visual>
    <collision>
      <origin
        xyz="0 0 0"
        rpy="0 0 0" />
      <geometry>
        <mesh
          filename="package://mobile_robot/meshes/link_1d.STL" />
      </geometry>
    </collision>
  </link>
  <joint
    name="joint_1d"
    type="fixed">
    <origin
      xyz="0.2365 0.06 0.219"
      rpy="1.5708 0 0.39187" />
    <parent
      link="base_link" />
    <child
      link="link_1d" />
    <axis
      xyz="0 0 0" />
  </joint>
  <link
    name="link_2">
    <inertial>
      <origin
        xyz="0.0537521021538062 2.77555756156289E-17 0.012417867361845"
        rpy="0 0 0" />
      <mass
        value="0.83985278956181" />
      <inertia
        ixx="0.00101033633411805"
        ixy="1.14413683967417E-18"
        ixz="0.000456321325264452"
        iyy="0.00380409172847024"
        iyz="2.3886409977526E-19"
        izz="0.00392594422883488" />
    </inertial>
    <visual>
      <origin
        xyz="0 0 0"
        rpy="0 0 0" />
      <geometry>
        <mesh
          filename="package://mobile_robot/meshes/link_2.STL" />
      </geometry>
      <material
        name="">
        <color
          rgba="0.792156862745098 0.819607843137255 0.933333333333333 1" />
      </material>
    </visual>
    <collision>
      <origin
        xyz="0 0 0"
        rpy="0 0 0" />
      <geometry>
        <mesh
          filename="package://mobile_robot/meshes/link_2.STL" />
      </geometry>
    </collision>
  </link>
  <joint
    name="joint_2"
    type="fixed">
    <origin
      xyz="-0.074188 0.0175 -0.08461"
      rpy="3.1416 0.39353 0" />
    <parent
      link="link_1d" />
    <child
      link="link_2" />
    <axis
      xyz="0 0 0" />
  </joint>
  <link
    name="link_3d">
    <inertial>
      <origin
        xyz="0.0429616361908162 0.0175 0.0248432505834826"
        rpy="0 0 0" />
      <mass
        value="0.351878584084715" />
      <inertia
        ixx="0.00120209563686855"
        ixy="-3.5613123466281E-20"
        ixz="0.000209154549476735"
        iyy="0.00145264496019541"
        iyz="-1.97938259373571E-19"
        izz="0.000316574406941379" />
    </inertial>
    <visual>
      <origin
        xyz="0 0 0"
        rpy="0 0 0" />
      <geometry>
        <mesh
          filename="package://mobile_robot/meshes/link_3d.STL" />
      </geometry>
      <material
        name="">
        <color
          rgba="0.792156862745098 0.819607843137255 0.933333333333333 1" />
      </material>
    </visual>
    <collision>
      <origin
        xyz="0 0 0"
        rpy="0 0 0" />
      <geometry>
        <mesh
          filename="package://mobile_robot/meshes/link_3d.STL" />
      </geometry>
    </collision>
  </link>
  <joint
    name="joint_3d"
    type="fixed">
    <origin
      xyz="0.22001 0 0.073186"
      rpy="-2.3562 0 1.5708" />
    <parent
      link="link_2" />
    <child
      link="link_3d" />
    <axis
      xyz="0 0 0" />
  </joint>
  <link
    name="wheel_d">
    <inertial>
      <origin
        xyz="0 -0.000325682611318989 0"
        rpy="0 0 0" />
      <mass
        value="1.54358472058328" />
      <inertia
        ixx="0.00553612528961153"
        ixy="2.76130854728311E-18"
        ixz="-3.03576608295941E-18"
        iyy="0.00957443122522794"
        iyz="-1.43498117338083E-19"
        izz="0.00553612528961153" />
    </inertial>
    <visual>
      <origin
        xyz="0 0 0"
        rpy="0 0 0" />
      <geometry>
        <mesh
          filename="package://mobile_robot/meshes/wheel_d.STL" />
      </geometry>
      <material
        name="">
        <color
          rgba="0.792156862745098 0.819607843137255 0.933333333333333 1" />
      </material>
    </visual>
    <collision>
      <origin
        xyz="0 0 0"
        rpy="0 0 0" />
      <geometry>
        <mesh
          filename="package://mobile_robot/meshes/wheel_d.STL" />
      </geometry>
    </collision>
  </link>
  <joint
    name="wheel_joint_d"
    type="continuous">
    <origin
      xyz="0 0.0175 -0.055"
      rpy="0 0.77621 1.5708" />
    <parent
      link="link_3d" />
    <child
      link="wheel_d" />
    <axis
      xyz="0 1 0" />
  </joint>
  <link
    name="lidar">
    <inertial>
      <origin
        xyz="1.16356825275844E-18 8.31876439690872E-18 0.0497497202049783"
        rpy="0 0 0" />
      <mass
        value="2.00013341899983" />
      <inertia
        ixx="0.00483668426767401"
        ixy="-2.16840434497101E-19"
        ixz="1.32977116051093E-19"
        iyy="0.00483668426767401"
        iyz="1.75346905687105E-19"
        izz="0.00637045764760341" />
    </inertial>
    <visual>
      <origin
        xyz="0 0 0"
        rpy="0 0 0" />
      <geometry>
        <mesh
          filename="package://mobile_robot/meshes/lidar.STL" />
      </geometry>
      <material
        name="">
        <color
          rgba="0.792156862745098 0.819607843137255 0.933333333333333 1" />
      </material>
    </visual>
    <collision>
      <origin
        xyz="0 0 0"
        rpy="0 0 0" />
      <geometry>
        <mesh
          filename="package://mobile_robot/meshes/lidar.STL" />
      </geometry>
    </collision>
  </link>
  <joint
    name="lidar_joint"
    type="fixed">
    <origin
      xyz="0 -0.151 0.0"
      rpy="-1.5708 0.44382 -3.1416" />
    <parent
      link="base_link" />
    <child
      link="lidar" />
    <axis
      xyz="0 0 1" />
  </joint>

# adding color to links
  <gazebo reference="base_link">
      <xacro:base_link_color />
  </gazebo>

  <gazebo reference="wheel_a">
      <xacro:wheel_color />
  </gazebo>

  <gazebo reference="wheel_b">
      <xacro:wheel_color />
  </gazebo>

  <gazebo reference="wheel_c">
      <xacro:wheel_color />
  </gazebo>

  <gazebo reference="wheel_d">
      <xacro:wheel_color />
  </gazebo>

# Controllers Start
  <ros2_control name="GazeboSystem" type="system">
  <hardware>
      <plugin>gazebo_ros2_control/GazeboSystem</plugin>
  </hardware>

 # Velocity Controllers

  <joint name="wheel_joint_a">
      <command_interface name="velocity">
          <param name="min">-1000.0</param>
          <param name="max">1000.0</param>
      </command_interface>
      <state_interface name="position"/>
      <state_interface name="velocity"/>
  </joint>

  <joint name="wheel_joint_b">
      <command_interface name="velocity">
          <param name="min">-1000.0</param>
          <param name="max">1000.0</param>
      </command_interface>
      <state_interface name="position"/>
      <state_interface name="velocity"/>
  </joint>

  <joint name="wheel_joint_c">
      <command_interface name="velocity">
          <param name="min">-1000.0</param>
          <param name="max">1000.0</param>
      </command_interface>
      <state_interface name="position"/>
      <state_interface name="velocity"/>
  </joint>

  <joint name="wheel_joint_d">
      <command_interface name="velocity">
          <param name="min">-1000.0</param>
          <param name="max">1000.0</param>
      </command_interface>
      <state_interface name="position"/>
      <state_interface name="velocity"/>
  </joint>

 # Position Controller
  <joint name="joint_3a">
      <command_interface name="position">
          <param name="min">-3.14</param>
          <param name="max">3.14</param>
      </command_interface>
      <state_interface name="position"/>
      <state_interface name="velocity"/>
  </joint>

  <joint name="joint_3b">
      <command_interface name="position">
          <param name="min">-3.14</param>
          <param name="max">3.14</param>
      </command_interface>
      <state_interface name="position"/>
      <state_interface name="velocity"/>
  </joint>

  </ros2_control>

  <gazebo>
      <plugin filename="libgazebo_ros2_control.so" name="gazebo_ros2_control">
          <parameters>$(find mobile_robot)/config/control.yaml</parameters>
      </plugin>
  </gazebo>
  #Controller end

#Lidar 
<gazebo reference="lidar">
  <sensor name="lidar" type="ray">
    <pose>0.0 0.0 0.0 0 0 0</pose>
    <always_on>true</always_on>
    <visualize>true</visualize>
    <update_rate>5</update_rate>
    <ray>
      <scan>
        <horizontal>
          <samples>360</samples>
          <resolution>1.00000</resolution>
          <min_angle>0.000000</min_angle>
          <max_angle>6.280000</max_angle>
        </horizontal>
      </scan>
      <range>
        <min>0.120000</min>
        <max>3.5</max>
        <resolution>0.015000</resolution>
      </range>
      <noise>
        <type>gaussian</type>
        <mean>0.0</mean>
        <stddev>0.01</stddev>
      </noise>
    </ray>
    <plugin name="scan" filename="libgazebo_ros_ray_sensor.so">
      <ros>
        <remapping>~/out:=scan</remapping>
      </ros>
      <output_type>sensor_msgs/LaserScan</output_type>
      <frame_name>lidar</frame_name>
    </plugin>
  </sensor>
  </gazebo>

 # IMU
 <gazebo reference="base_link">
  <gravity>true</gravity>
  <sensor name="imu_sensor" type="imu">
    <always_on>true</always_on>
    <update_rate>100</update_rate>
    <visualize>true</visualize>
    <topic>__default_topic__</topic>
    <plugin filename="libgazebo_ros_imu_sensor.so" name="imu_plugin">
      <topicName>imu</topicName>
      <bodyName>base_link</bodyName>
      <updateRateHZ>10.0</updateRateHZ>
      <gaussianNoise>0.0</gaussianNoise>
      <xyzOffset>0 0 0</xyzOffset>
      <rpyOffset>0 0 0</rpyOffset>
      <frameName>base_link</frameName>
      <initialOrientationAsReference>false</initialOrientationAsReference>
    </plugin>
    <pose>0 0 0 0 0 0</pose>
  </sensor>
</gazebo>


</robot>